<?xml version="1.0"?>
<robot name="diff_bot">
    <!-- <link name="base_footprint">
        <inertial>
            <origin xyz="0.0 0.0 0.0" rpy="0.0 0.0 0.0"/>
            <mass value="0.0001"/>
            <inertia ixx="0.0001" ixy="0.0" ixz="0.0" iyy="0.0001" iyz="0.0" izz="0.0001"/>
        </inertial>
        <visual name="base_footprint_visual">
            <origin xyz="0.0 0.0 0.0" rpy="0.0 0.0 0.0"/>
            <geometry>
                <box size="0.001 0.001 0.001"/>
            </geometry>
        </visual>
    </link>
    <gazebo reference="base_footprint">
        <turnGravityOff>false</turnGravityOff>
    </gazebo>
    <joint name="base_footprint_joint" type="fixed">
        <origin xyz="0.0 0.0 0.1" rpy="0.0 0.0 0.0"/>
        <parent link="base_footprint"/>
        <child link="base_link"/>
        <update_rate>20</update_rate>
    </joint> -->
    <link name="base_link">
        <pose>0 0 0 0 0 0</pose>
        <inertial>
            <!-- <mass value="50"/>
            <origin rpy="0 0 0" xyz="0 0 0"/>
            <inertia ixx="0.395416666667" ixy="0" ixz="0" iyy="1.06208333333" iyz="-1.0" izz="1.06208333333"/> -->
            <mass value="15"/>
            <origin rpy="0 0 0" xyz="0 0 0"/>
            <inertia ixx="1.0" ixy="0" ixz="0" iyy="0.0" iyz="1.0" izz="0.0"/>
        </inertial>
        <visual name="base_link_visual" >
            <origin xyz="0.0 0.0 0.0" rpy="0.0 0.0 0.0"/>
            <geometry>
                <box size=".5 .3 .1"/>
            </geometry>
        </visual> 
        <collision>
            <origin xyz="0.0 0.0 0.0" rpy="0.0 0.0 0.0"/>
            <geometry>
                <box size=".5 .3 .1"/>
            </geometry>
        </collision>
        <collision name="caster_front_collision">
            <origin rpy=" 0 0 0" xyz="0.35 0.0 -0.05"/>
            <geometry>
                <sphere radius="0.05"/>
            </geometry>
            <surface>
                <friction>
                <ode>
                    <mu>0</mu>
                    <mu2>0</mu2>
                    <slip1>1.0</slip1>
                    <slip2>1.0</slip2>
                </ode>
                </friction>
            </surface>
        </collision>
        <visual name="caster_front_visual">
            <origin rpy=" 0 0 0" xyz="0.2 0 -0.05"/>
            <geometry>
                <sphere radius="0.05"/>
            </geometry>
        </visual>  
    </link>
    
    <gazebo reference="base_link">
    		<material>Gazebo/White</material>
            <turnGravityOff>false</turnGravityOff>
  	</gazebo>
    <!-- <link name="caster_link">
        <visual>
            <origin rpy="0 0 0" xyz="0.2 0.0 -0.05"/>
            <geometry>
                <sphere radius="0.05"/>
            </geometry>
        </visual>
        <collision>
            <geometry>
                <sphere radius="0.05"/>
            </geometry>
            <origin rpy="0 0 0" xyz="0.35 0.0 -0.05"/>
        </collision>
        <inertial>
            <mass value="0.5"/>
            <origin xyz="0 0 0"/>
            <inertia ixx="0.001" ixy="0.0" ixz="0.0" iyy="0.001" iyz="0.0" izz="0.001"/>
        </inertial>
  </link>
  <joint name="caster_joint" type="fixed">
    <parent link="base_link"/>
    <child link="caster_link"/>
    <origin rpy="-1.57079632679 0 0" xyz="0.2 0.0 -0.05"/>
  </joint>
  <gazebo reference="caster_link">
    <turnGravityOff>false</turnGravityOff>
  </gazebo> -->
    <link name="left_wheel">
        <inertial>
            <mass value="1"/>
            <origin xyz="-0.1 0.0 0.0" rpy="0.0 0 0"/>
            <inertia ixx="1" ixy="0" ixz="0" iyy="1" iyz="0" izz="1"/>
        </inertial>
        <visual name="left_wheel_visual" >
            <origin xyz="0.0 0.0 0.0" rpy="1.5707 0.0 0.0"/>
            <geometry>
                <cylinder radius="0.1" length="0.03"/>
            </geometry>
            <material name="white">
                <color rgba="1.0 0.0 0.0 1.0"/>
            </material>
        </visual>
        <collision name="link_left_wheel_collision">
            <origin xyz="0.0 0.0 0.0" rpy="1.5707 0 0"/>
            <geometry>
                <cylinder radius="0.1" length="0.03"/>
            </geometry>
        </collision>
    </link>
    <joint name="left_wheel_joint" type="continuous">
        <origin xyz="-0.15 -0.15 0.0" rpy="0.0 0.0 0.0"/>
        <parent link="base_link"/>
        <child link="left_wheel"/>
        <axis xyz="0.0 1.0 0.0"/>
        <update_rate>20</update_rate>
        <limit effort="100.0" velocity="100.0"/>
        <joint_properties damping="0.0" friction="0.0"/>
    </joint>
    <transmission name="tran_left">
        <type>transmission_interface/SimpleTransmission</type>
        <joint name="left_wheel_joint">
            <hardwareInterface>EffortJointInterface</hardwareInterface>
        </joint>
        <actuator name="motor_left">
            <hardwareInterface>EffortJointInterface</hardwareInterface>
            <mechanicalReduction>1</mechanicalReduction>
        </actuator>
    </transmission>
     <gazebo reference="left_wheel">
        <mu1 value="1.0"/>
        <mu2 value="1.0"/>
        <update_rate>20</update_rate>
        <kp value="1.0"/>
        <kd value="00.0"/>
        <ki value="0.0"/>
        <fdir1 value="1 0 0"/>
        <material>Gazebo/Grey</material>
        <turnGravityOff>false</turnGravityOff>
    </gazebo>
    <link name="right_wheel">
        <inertial>
            <mass value="1"/>
            <origin xyz="-0.1 0.0 0.0" rpy="0.0 0 0"/>
            <inertia ixx="1" ixy="0" ixz="0" iyy="1" iyz="0" izz="1"/>
        </inertial>
        <visual name="right_wheel_visual" >
            <origin xyz="0.0 0.0 0.0" rpy="1.5707 0.0 0.0"/>
            <geometry>
                <cylinder radius="0.1" length="0.03"/>
            </geometry>
            <material name="white">
                <color rgba="1.0 0.0 0.0 1.0"/>
            </material>
        </visual>
        <collision name="link_right_wheel_collision">
            <origin xyz="0.0 0.0 0.0" rpy="1.5707 0 0"/>
            <geometry>
                <cylinder radius="0.1" length="0.03"/>
            </geometry>
        </collision>
    </link>
    <joint name="right_wheel_joint" type="continuous">
        <origin xyz="-0.15 0.15 0.0" rpy="0.0 0.0 0.0"/>
        <parent link="base_link"/>
        <child link="right_wheel"/>
        <update_rate>20</update_rate>
        <axis xyz="0.0 1.0 0.0"/>
        <limit effort="100.0" velocity="100.0"/>
        <joint_properties damping="0.0" friction="0.0"/>
    </joint>
    <transmission name="tran_right">
        <type>transmission_interface/SimpleTransmission</type>
        <joint name="right_wheel_joint">
            <hardwareInterface>EffortJointInterface</hardwareInterface>
        </joint>
        <actuator name="motor_right">
            <hardwareInterface>EffortJointInterface</hardwareInterface>
            <mechanicalReduction>1</mechanicalReduction>
        </actuator>
    </transmission>
     <gazebo reference="right_wheel">
        <mu1 value="1.0"/>
        <mu2 value="1.0"/>
        <update_rate>20</update_rate>
        <kp value="1.0"/>
        <kd value="0.0"/>
        <ki value="0.0"/>
        <fdir1 value="1 0 0"/>
        <material>Gazebo/Grey</material>
        <turnGravityOff>false</turnGravityOff>
    </gazebo>
    <!-- <link name="caster_back_link">
        <visual>
            <origin rpy="1.57079632679 0 0" xyz="0.02 0.02 0 "/>
            <geometry>
                <sphere radius="0.025"/>
            </geometry>
        </visual>
        <collision>
            <geometry>
                <sphere radius="0.025"/>
            </geometry>
            <origin rpy="1.57079632679 0 0" xyz="0 0.02 0 "/>
        </collision>
        <inertial>
            <mass value="0.5"/>
            <origin xyz="0 0 0"/>
            <inertia ixx="0.001" ixy="0.0" ixz="0.0" iyy="0.001" iyz="0.0" izz="0.001"/>
        </inertial>
    </link>
    <joint name="caster_back_joint" type="fixed">
        <parent link="base_link"/>
        <child link="caster_back_link"/>
        <origin rpy="-1.57079632679 0 0" xyz="-0.135 0.0 0.009"/>
    </joint>
    <gazebo reference="caster_back_link">
        <turnGravityOff>false</turnGravityOff>
    </gazebo> -->
    <!-- <link name="right_wheel">
        <inertial>
            <mass value="2.5"/>
            <origin xyz="-0.2 0.0 0.0" rpy="0.0 0 0"/>
            <inertia ixx="0.00108333333333" ixy="0" ixz="0" iyy="0.00108333333333" iyz="0" izz="0.002"/>
        </inertial>
        <visual name="right_wheel_visual" >
            <origin xyz="-0.2 0.0 0.0" rpy="1.5707 0.0 0.0"/>
            <geometry>
                <cylinder radius="0.1" length="0.04"/>
            </geometry>
            <material name="white">
                <color rgba="1.0 0.0 0.0 1.0"/>
            </material>
        </visual>
        <collision name="link_right_wheel_collision">
            <origin xyz="-0.2 0.0 0.0" rpy="1.5707 0 0"/>
            <geometry>
                <cylinder radius="0.1" length="0.04"/>
            </geometry>
        </collision>
    </link>
    <gazebo reference="right_wheel">
        <mu1 value="1.0"/>
        <mu2 value="1.0"/>
        <kp value="1.0"/>
        <kd value="1.0"/>
        <fdir1 value="1 0 0"/>
        <material>Gazebo/Grey</material>
        <turnGravityOff>false</turnGravityOff>
    </gazebo>
    <joint name="right_wheel_joint" type="continuous">
        <origin xyz="0.0 0.15 0.0" rpy="0.0 0.0 0.0"/>
        <parent link="base_link"/>
        <child link="right_wheel"/>
        <axis xyz="0.0 1.0 0.0"/>
        <limit effort="100.0" velocity="100.0"/>
        <joint_properties damping="0.0" friction="0.0"/>
    </joint>
    <transmission name="tran_right">
        <type>transmission_interface/SimpleTransmission</type>
        <joint name="right_wheel_joint">
            <hardwareInterface>EffortJointInterface</hardwareInterface>
        </joint>
        <actuator name="motor_right">
            <hardwareInterface>EffortJointInterface</hardwareInterface>
            <mechanicalReduction>1</mechanicalReduction>
        </actuator>
    </transmission> -->
    <link name="laser">
        <inertial>
            <mass value='0.2'/>
            <origin xyz="0.0 0.0 0.0105" rpy="0.0 0.0 0.0"/>
      	    <inertia ixx="0.0395416666667" ixy="0" ixz="0" iyy="0.106208333333" iyz="0" izz="0.106208333333"/>
        </inertial>
        <visual name="laser_visual" >
            <origin xyz="0.0 0.0 0.0" rpy="0.0 0.0 0.0"/>
            <geometry>
                <cylinder radius="0.001" length="0.1"/>
            </geometry>
            <material name="white_2">
                <color rgba="1.0 0.0 0.0 1.0"/>
            </material>
        </visual>
    </link>
    
    <joint name="laser_joint" type="fixed">
	    <parent link = "base_link"/>
	    <child link = "laser"/>
	    <origin xyz="0 0 0.12" rpy="0 0 0"/>
    </joint>
    
    <gazebo reference="laser">
        <!-- <publishTf>true</publishTf> -->
		<sensor type="ray" name="laser sensor">
			<pose> 0 0 0 0 0 0 </pose>
			<visualize>true</visualize>
			<update_rate>20.0</update_rate>
			<ray>
				<scan>
					<horizontal>
						<samples>720</samples>
						<resolution>1</resolution>
						<min_angle>-3.13</min_angle>
						<max_angle>3.14</max_angle>
					</horizontal>
				</scan>
				<range>
					<min>0.2</min>
					<max>2.0</max>
					<resolution>0.1</resolution>
				</range>
				<noise>
					<type>gaussian</type>
					<mean>0.0</mean>
					<stddev>0.01</stddev>
				</noise>
			</ray>
			<plugin name="gazebo_ros_laser_scan" filename="libgazebo_ros_laser.so">
				<topicName>/diff_bot/laser/scan</topicName>
				<frameName>laser</frameName>
			</plugin>
		</sensor>
	</gazebo>
    <gazebo>
	    <plugin name="imu_plugin" filename="libgazebo_ros_imu.so">
	      <alwaysOn>true</alwaysOn>
	      <bodyName>base_link</bodyName>
	      <topicName>imu</topicName>
	      <serviceName>imu_service</serviceName>
	      <gaussianNoise>1.0</gaussianNoise>
	      <updateRate>20.0</updateRate>
          <frameName>base_link</frameName>
	    </plugin>
  	</gazebo>
    
    <gazebo>
		<plugin name="gazebo_ros_control" filename="libgazebo_ros_control.so">
		    <robotNamespace>/diff_bot</robotNamespace>
		</plugin>
	</gazebo>
    <gazebo>
    <plugin filename="libgazebo_ros_diff_drive.so" name="differential_drive_controller_front">
      <!-- <rosDebugLevel>Debug</rosDebugLevel> -->
      <publishWheelTF>false</publishWheelTF>
      <publishTf>true</publishTf>
      <publishWheelJointState>true</publishWheelJointState>
      <alwaysOn>true</alwaysOn>
      <updateRate>100.0</updateRate>
      <leftJoint>left_wheel_joint</leftJoint>
      <rightJoint>right_wheel_joint</rightJoint>
      <wheelSeparation>0.34</wheelSeparation>
      <wheelDiameter>0.2</wheelDiameter>
      <wheelTorque>10</wheelTorque>
      <wheelAcceleration>1.8</wheelAcceleration>
      <commandTopic>cmd_vel</commandTopic>
      <odometrySource>world</odometrySource>
      <broadcastTF>1</broadcastTF>
      <odometryFrame>odom</odometryFrame>
      <odometryTopic>odom</odometryTopic>
      <publishOdom>True</publishOdom>
      <robotBaseFrame>base_link</robotBaseFrame>
    </plugin>
  </gazebo>
</robot>
