<?xml version="1.0"?>
<robot name="diff_bot">
    <!-- <link name="base_footprint"/> -->
    <link name="base_link">
        <pose>0 0 0.1 0 0 0</pose>
        <inertial>
            <mass value="10.0"/>
            <origin rpy=" 0 0 0" xyz="0.0 0 0.1"/>
            <inertia ixx=".50" ixy="0.0" ixz="0.0" iyy="1.0" iyz="0.0" izz=".10"/>
        </inertial>
        <collision name="collision">
        <geometry>
            <box size=".4 .2 .1"/>
        </geometry>
        </collision>
        <visual name="base_link_visual">
            <origin rpy=" 0 0 0" xyz="0 0 0"/>
            <geometry>
                <box size=".4 .2 .1"/>
            </geometry>
        </visual>
        <collision name="caster_collision">
            <origin rpy=" 0 0 0" xyz="-0.15 0 -0.05"/>
            <geometry>
                <sphere radius="0.05"/>
            </geometry>
            <surface>
                <friction>
                <ode>
                    <mu>0</mu>
                    <mu2>0</mu2>
                    <slip1>1.0</slip1>
                    <slip2>1.0</slip2>
                </ode>
                </friction>
            </surface>
        </collision>
        <visual name="caster_visual">
            <origin rpy=" 0 0 0" xyz="-0.15 0 -0.05"/>
            <geometry>
                <sphere radius="0.05"/>
            </geometry>
        </visual>
    </link>
    <gazebo reference="base_link">
    		<material>Gazebo/White</material>
            <turnGravityOff>false</turnGravityOff>
            <kp>1000000.0</kp>
            <kd>100.0</kd>
            <minDepth>0.001</minDepth>
    <maxVel>1.0</maxVel>
  	</gazebo>
    <link name="left_wheel">
        <!--origin xyz="0.1 0.13 0.1" rpy="0 1.5707 1.5707"/-->
        <collision name="collision">
            <origin rpy="0 1.5707 1.5707" xyz="0 0 0"/>
            <geometry>
                <cylinder length="0.05" radius="0.1"/>
            </geometry>
        </collision>
        <visual name="left_wheel_visual">
            <origin rpy="0 1.5707 1.5707" xyz="0 0 0"/>
            <geometry>
                <cylinder length="0.05" radius="0.1"/>
            </geometry>
        </visual>
        <inertial>
            <origin rpy="0 1.5707 1.5707" xyz="0 0 0"/>
            <mass value="5"/>
            <cylinder_inertia h="0.05" m="5" r="0.1"/>
            <inertia ixx="1.0" ixy="0.0" ixz="0.0" iyy="1.0" iyz="0.0" izz="1.0"/>
        </inertial>
    </link>
    <link name="right_wheel">
        <!--origin xyz="0.1 -0.13 0.1" rpy="0 1.5707 1.5707"/-->
        <collision name="collision">
            <origin rpy="0 1.5707 1.5707" xyz="0 0 0"/>
            <geometry>
                <cylinder length="0.05" radius="0.1"/>
            </geometry>
        </collision>
        <visual name="right_wheel_visual">
            <origin rpy="0 1.5707 1.5707" xyz="0 0 0"/>
            <geometry>
                <cylinder length="0.05" radius="0.1"/>
            </geometry>
        </visual>
        <inertial>
            <origin rpy="0 1.5707 1.5707" xyz="0 0 0"/>
            <mass value="5"/>
            <cylinder_inertia h="0.05" m="5" r="0.1"/>
            <inertia ixx="1.0" ixy="0.0" ixz="0.0" iyy="1.0" iyz="0.0" izz="1.0"/>
        </inertial>
    </link>
    <joint name="left_wheel_joint" type="continuous">
        <origin xyz="0.1 0.15 0" rpy="0 0 0"/>
        <child link="left_wheel"/>
        <parent link="base_link"/>
        <axis xyz="0 1 0" rpy="0 0 0"/>
        <limit effort="100" velocity="100"/>
        <joint_properties damping="0.0" friction="0.0"/>
    </joint>
    <transmission name="tran_left">
        <type>transmission_interface/SimpleTransmission</type>
        <joint name="left_wheel_joint">
            <hardwareInterface>EffortJointInterface</hardwareInterface>
        </joint>
        <actuator name="motor_left">
            <hardwareInterface>EffortJointInterface</hardwareInterface>
            <mechanicalReduction>1</mechanicalReduction>
        </actuator>
    </transmission>
     <gazebo reference="left_wheel">
        <mu1 value="1.0"/>
        <mu2 value="1.0"/>
        <update_rate>20</update_rate>
        <kp value="1000000.0"/>
        <kd value="1.0"/>
        <!-- <ki value="1.0"/> -->
        <fdir1 value="1 0 0"/>
        <material>Gazebo/Grey</material>
        <turnGravityOff>false</turnGravityOff>
    </gazebo>
    
    <joint name="right_wheel_joint" type="continuous">
        <origin xyz="0.1 -0.15 0" rpy="0 0 0"/>
        <child link="right_wheel"/>
        <parent link="base_link"/>
        <axis xyz="0 1 0" rpy="0 0 0"/>
        <limit effort="100" velocity="100"/>
        <joint_properties damping="0.0" friction="0.0"/>
    </joint>
    <transmission name="tran_right">
        <type>transmission_interface/SimpleTransmission</type>
        <joint name="right_wheel_joint">
            <hardwareInterface>EffortJointInterface</hardwareInterface>
        </joint>
        <actuator name="motor_right">
            <hardwareInterface>EffortJointInterface</hardwareInterface>
            <mechanicalReduction>1</mechanicalReduction>
        </actuator>
    </transmission>
     <gazebo reference="right_wheel">
        <mu1 value="1.0"/>
        <mu2 value="1.0"/>
        <update_rate>20</update_rate>
        <kp value="10000000.0"/>
        <kd value="1.0"/>
        <!-- <ki value="1.0"/> -->
        <fdir1 value="1 0 0"/>
        <material>Gazebo/Grey</material>
        <turnGravityOff>false</turnGravityOff>
    </gazebo>
    <gazebo> 
	    <plugin name="imu_plugin" filename="libgazebo_ros_imu.so">
	      <alwaysOn>true</alwaysOn>
	      <bodyName>base_link</bodyName>
	      <topicName>imu</topicName>
	      <serviceName>imu_service</serviceName>
	      <gaussianNoise>1.0</gaussianNoise>
	      <updateRate>20.0</updateRate>
          <frameName>base_link</frameName>
	    </plugin>
  	</gazebo>
    
  
    <gazebo>
        <plugin name="gazebo_ros_control" filename="libgazebo_ros_control.so">
            <robotSimType>gazebo_ros_control/DefaultRobotHWSim</robotSimType>
            <legacyModeNS>true</legacyModeNS>
            <odometryTopic>odom</odometryTopic>
            <odometryFrame>odom</odometryFrame>
            <odometrySource>world</odometrySource>
            <publishOdomTF>true</publishOdomTF>
        </plugin>
    </gazebo>

  
    <gazebo>
        <plugin name="robot_groundtruth_sim" filename="libgazebo_ros_p3d.so">
            <alwaysOn>true</alwaysOn>
            <updateRate>100.0</updateRate>
            <bodyName>base_link</bodyName>
            <topicName>odom</topicName>
            <frameName>world</frameName>
        </plugin>
    </gazebo>
    <!-- <gazebo>
        <plugin filename="libgazebo_ros_diff_drive.so" name="differential_drive_controller_front">
            <rosDebugLevel>Debug</rosDebugLevel>
            <publishWheelTF>false</publishWheelTF>
            <publishTf>true</publishTf>
            <publishWheelJointState>true</publishWheelJointState>
            <alwaysOn>true</alwaysOn>
            <updateRate>100.0</updateRate>
            <leftJoint>left_wheel_joint</leftJoint>
            <rightJoint>right_wheel_joint</rightJoint>
            <wheelSeparation>0.4</wheelSeparation>
            <wheelDiameter>0.2</wheelDiameter>
            <wheelTorque>10.0</wheelTorque>
            <wheelAcceleration>1.8</wheelAcceleration>
            <commandTopic>cmd_vel</commandTopic>
            <odometrySource>world</odometrySource>
            <broadcastTF>10.0</broadcastTF>
            <odometryFrame>odom</odometryFrame>
            <odometryTopic>odom</odometryTopic>
            <publishOdom>True</publishOdom>
            <robotBaseFrame>base_link</robotBaseFrame>
        </plugin>
    </gazebo> -->
</robot> 