<?xml version="1.0"?>
<robot name="sample_bot">
    <link name ="base_footprint"/>
    <link name="base_link">
        <inertial>
            <origin xyz="0.0 0.0 0.1" rpy="0.0 0.0 0.0"/>
            <mass value="10.0"/>
            <inertia ixx="0.5" ixy="0.0" ixz="0.0" iyy="1.0" iyz="0.0" izz="0.1"/>
        </inertial>
        <visual>
            <geometry>
                <box size="0.4 0.2 0.1"/>
            </geometry>
        </visual>
        <collision>
            <origin xyz="0.0 0.0 0.0" rpy="0.0 0.0 0.0"/>
            <geometry>
                <box size="0.0 0.0 0.0"/>
            </geometry>
        </collision>
    </link>
    <link name="left_wheel">
        <inertial>
            <origin xyz="0.1 0.13 0.1" rpy="0.0 1.5707 1.5707"/>
        </inertial>
        <visual>
            <geometry>
                <cylinder radius="0.1" length="0.05"/>
            </geometry>
            <material>
                <color rgba="1.0 0.0 0.0 1.0"/>
            </material>
        </visual>
        <collision>
            <geometry>
                <cylinder radius="0.1" length="0.05"/>
            </geometry>
        </collision>
    </link>
    <link name="right_wheel">
        <ine-rtial>
            <origin xyz="0.1 -0.13 0.1" rpy="0.0 1.5707 1.5707"/>
        </inertial>
        <visual>
            <geometry>
                <cylinder radius="0.1" length="0.05"/>
            </geometry>
            <material>
                <color rgba="1.0 0.0 0.0 1.0"/>
            </material>
        </visual>
        <collision>
            <geometry>
                <cylinder radius="0.1" length="0.05"/>
            </geometry>
        </collision>
    </link>
    <link name="laser">
        <inertial>
            <origin xyz="0.0 0.0 0.0045" rpy="0.0 0.0 0.0"/>
        </inertial>
        <visual>
            <origin xyz="0.0 0.0 0.0" rpy="0.0 0.0 0.0"/>
            <geometry>
                <cylinder radius="0.001" length="0.1"/>
            </geometry>
            <material>
                <color rgba="1.0 0.0 0.0 1.0"/>
            </material>
        </visual>
    </link>
    <joint name="base_footprint_joint" type="fixed">
        <origin xyz="0.0 0.0 0.0" rpy="0.0 0.0 0.0"/>
        <parent link="base_footprint"/>
        <child link="base_link"/>
        <axis xyz="0.0 0.0 0.0"/>
    </joint>
    <joint name="left_wheel_joint" type="revolute">
        <origin xyz="0.0 0.0 -0.03" rpy="0.0 0.0 0.0"/>
        <parent link="base_link"/>
        <child link="left_wheel"/>
        <axis xyz="0.0 1.0 0.0"/>
    </joint>
    <transmission name="tran_left">
        <type>transmission_interface/SimpleTransmission</type>
        <joint name="left_wheel_joint">
            <hardwareInterface>EffortJointInterface</hardwareInterface>
        </joint>
        <actuator name="motor_left">
            <hardwareInterface>EffortJointInterface</hardwareInterface>
            <mechanicalReduction>1</mechanicalReduction>
        </actuator>
    </transmission>
    <joint name="right_wheel_joint" type="revolute">
        <origin xyz="0.0 0.0 0.03" rpy="0.0 0.0 0.0"/>
        <parent link="base_link"/>
        <child link="right_wheel"/>
        <axis xyz="0.0 1.0 0.0"/>
    </joint>
    <transmission name="tran_right">
        <type>transmission_interface/SimpleTransmission</type>
        <joint name="right_wheel_joint">
            <hardwareInterface>EffortJointInterface</hardwareInterface>
        </joint>
        <actuator name="motor_right">
            <hardwareInterface>EffortJointInterface</hardwareInterface>
            <mechanicalReduction>1</mechanicalReduction>
        </actuator>
    </transmission>
    <joint name="laser_joint" type="fixed">
	    <parent link = "base_link"/>
	    <child link = "laser"/>
	    <origin xyz="0 0 0.070" rpy="0 0 0"/>
    </joint>
    
    <gazebo reference="laser">
		<sensor type="ray" name="laser sensor">
			<pose> 0 0 0 0 0 0 </pose>
			<visualize>true</visualize>
			<update_rate>100</update_rate>
			<ray>
				<scan>
					<horizontal>
						<samples>720</samples>
						<resolution>1</resolution>
						<min_angle>-3.13</min_angle>
						<max_angle>3.14</max_angle>
					</horizontal>
				</scan>
				<range>
					<min>0.2</min>
					<max>2.0</max>
					<resolution>0.1</resolution>
				</range>
				<noise>
					<type>gaussian</type>
					<mean>0.0</mean>
					<stddev>0.01</stddev>
				</noise>
			</ray>
			<plugin name="gazebo_ros_laser_scan" filename="libgazebo_ros_laser.so">
				<topicName>/sample_bot/laser/scan</topicName>
				<frameName>laser</frameName>
			</plugin>
		</sensor>
	</gazebo>
    <gazebo>
	    <plugin name="imu_plugin" filename="libgazebo_ros_imu.so">
	      <alwaysOn>true</alwaysOn>
	      <bodyName>base_link</bodyName>
	      <topicName>imu</topicName>
	      <serviceName>imu_service</serviceName>
	      <gaussianNoise>0.0</gaussianNoise>
	      <updateRate>20.0</updateRate>
	    </plugin>
  	</gazebo>
    <gazebo reference="base_link">
    		<material>Gazebo/White</material>
  	</gazebo>
    <gazebo>
		<plugin name="gazebo_ros_control" filename="libgazebo_ros_control.so">
		    <robotNamespace>/sample_bot</robotNamespace>
		</plugin>
	</gazebo>
    <gazebo>
    <plugin filename="libgazebo_ros_diff_drive.so" name="differential_drive_controller_front">
      <rosDebugLevel>Debug</rosDebugLevel>
      <publishWheelTF>True</publishWheelTF>
      <publishTf>1</publishTf>
      <publishWheelJointState>true</publishWheelJointState>
      <alwaysOn>true</alwaysOn>
      <updateRate>100.0</updateRate>
      <leftJoint>left_joint</leftJoint>
      <rightJoint>right_joint</rightJoint>
      <wheelSeparation>0.3</wheelSeparation>
      <wheelDiameter>0.08</wheelDiameter>
      <broadcastTF>1</broadcastTF>
      <wheelTorque>30</wheelTorque>
      <wheelAcceleration>1.8</wheelAcceleration>
      <commandTopic>cmd_vel</commandTopic>
      <odometryFrame>odom</odometryFrame>
      <odometryTopic>odom</odometryTopic>
      <robotBaseFrame>base_link</robotBaseFrame>
    </plugin>
  </gazebo>
</robot>
